Workbook

Sheet ЭТАПЫ
A1: Ситуация | B1: Этап №1 | F1: Этап №2 | J1: Этап №3
B2: Вероят. | C2: ЦБ1 | D2: ЦБ2 | E2: Деп. | F2: Вероят. | G2: ЦБ1 | H2: ЦБ2 | I2: Деп. | J2: Вероят. | K2: ЦБ1 | L2: ЦБ2 | M2: Деп.
A3: Благопр. | B3: 0.6 | C3: 1.2 | D3: 1.1 | E3: 1.07 | F3: 0.3 | G3: 1.4 | H3: 1.15 | I3: 1.01 | J3: 0.4 | K3: 1.15 | L3: 1.12 | M3: 1.05
A4: Нейтр. | B4: 0.3 | C4: 1.05 | D4: 1.02 | E4: 1.03 | F4: 0.2 | G4: 1.05 | H4: 1 | I4: 1 | J4: 0.4 | K4: 1.05 | L4: 1.01 | M4: 1.01
A5: Негатив. | B5: 0.1 | C5: 0.8 | D5: 0.95 | E5: 1 | F5: 0.5 | G5: 0.6 | H5: 0.9 | I5: 1 | J5: 0.2 | K5: 0.7 | L5: 0.94 | M5: 1
B7: ЦБ1 | C7: ЦБ2 | D7: Деп. | E7: Свободно
A8: Начальные данные | B8: 100 | C8: 800 | D8: 400 | E8: 600
A9: Шаг изменения | B9: 25 | C9: 200 | D9: 100
A11: Ограничения, не менее
A12: ЦБ1 | B12: ЦБ2 | C12: Деп.
A13: 30 | B13: 150 | C13: 100
A15: Комиссии брокеров
A16: ЦБ1 | B16: ЦБ2 | C16: Деп.
A17: 0.04 | B17: 0.07 | C17: 0.05

Sheet Решение
A1: Решение | G1: Формулы
B3: Минимальные ограничения
B4: ЦБ1 | C4: ЦБ2 | D4: Деп.
B5: =ЭТАПЫ!A13 -> 30 | C5: =ЭТАПЫ!B13 -> 150 | D5: =ЭТАПЫ!C13 -> 100
A7: Этап 1 | G7: =IFERROR(_xlfn.FORMULATEXT(B7),B7) -> 0 | H7: =IFERROR(_xlfn.FORMULATEXT(C7),C7) -> 0 | I7: =IFERROR(_xlfn.FORMULATEXT(D7),D7) -> 0
B8: Переменные | E8: Свободные деньги (остаток) | G8: =IFERROR(_xlfn.FORMULATEXT(B8),B8) -> Переменные | H8: =IFERROR(_xlfn.FORMULATEXT(C8),C8) -> 0 | I8: =IFERROR(_xlfn.FORMULATEXT(D8),D8) -> 0
B9: Сколько шагов добавить в ЦБ1 | C9: Сколько шагов добавить в ЦБ2 | D9: Сколько шагов добавить в Деп. | G9: =IFERROR(_xlfn.FORMULATEXT(B9),B9) -> Сколько шагов добавить в ЦБ1 | H9: =IFERROR(_xlfn.FORMULATEXT(C9),C9) -> Сколько шагов добавить в ЦБ2 | I9: =IFERROR(_xlfn.FORMULATEXT(D9),D9) -> Сколько шагов добавить в Деп.
B10: x1 | C10: x2 | D10: x3 | G10: =IFERROR(_xlfn.FORMULATEXT(B10),B10) -> x1 | H10: =IFERROR(_xlfn.FORMULATEXT(C10),C10) -> x2 | I10: =IFERROR(_xlfn.FORMULATEXT(D10),D10) -> x3
B11: 2 | C11: 0 | D11: 5 | G11: =IFERROR(_xlfn.FORMULATEXT(B11),B11) -> 2 | H11: =IFERROR(_xlfn.FORMULATEXT(C11),C11) -> 0 | I11: =IFERROR(_xlfn.FORMULATEXT(D11),D11) -> 5
A12: Изменения в деньгах | B12: =B11*ЭТАПЫ!B9 -> 50 | C12: =C11*ЭТАПЫ!C9 -> 0 | D12: =D11*ЭТАПЫ!D9 -> 500 | E12: =ЭТАПЫ!E8-B12-C12-D12-ABS(Решение!B12)*ЭТАПЫ!A17-ABS(Решение!C12)*ЭТАПЫ!B17-ABS(Решение!D12)*ЭТАПЫ!C17 -> 23 | G12: =IFERROR(_xlfn.FORMULATEXT(B12),B12) -> 50 | H12: =IFERROR(_xlfn.FORMULATEXT(C12),C12) -> 0 | I12: =IFERROR(_xlfn.FORMULATEXT(D12),D12) -> 500
G13: =IFERROR(_xlfn.FORMULATEXT(B13),B13) -> 0 | H13: =IFERROR(_xlfn.FORMULATEXT(C13),C13) -> 0 | I13: =IFERROR(_xlfn.FORMULATEXT(D13),D13) -> 0
A14: Начальные значения | B14: Всего ЦБ1 | C14: Всего ЦБ2 | D14: Всего Деп. | G14: =IFERROR(_xlfn.FORMULATEXT(B14),B14) -> Всего ЦБ1 | H14: =IFERROR(_xlfn.FORMULATEXT(C14),C14) -> Всего ЦБ2 | I14: =IFERROR(_xlfn.FORMULATEXT(D14),D14) -> Всего Деп.
B15: =ЭТАПЫ!B8+B12 -> 150 | C15: =ЭТАПЫ!C8+Решение!C12 -> 800 | D15: =ЭТАПЫ!D8+Решение!D12 -> 900 | G15: =IFERROR(_xlfn.FORMULATEXT(B15),B15) -> 150 | H15: =IFERROR(_xlfn.FORMULATEXT(C15),C15) -> 800 | I15: =IFERROR(_xlfn.FORMULATEXT(D15),D15) -> 900
G16: =IFERROR(_xlfn.FORMULATEXT(B16),B16) -> 0 | H16: =IFERROR(_xlfn.FORMULATEXT(C16),C16) -> 0 | I16: =IFERROR(_xlfn.FORMULATEXT(D16),D16) -> 0
A17: Ситуация | B17: Результат в конце этапа | G17: =IFERROR(_xlfn.FORMULATEXT(B17),B17) -> Результат в конце этапа | H17: =IFERROR(_xlfn.FORMULATEXT(C17),C17) -> 0 | I17: =IFERROR(_xlfn.FORMULATEXT(D17),D17) -> 0
B18: ЦБ1 | C18: ЦБ2 | D18: Деп. | E18: Итого | G18: =IFERROR(_xlfn.FORMULATEXT(B18),B18) -> ЦБ1 | H18: =IFERROR(_xlfn.FORMULATEXT(C18),C18) -> ЦБ2 | I18: =IFERROR(_xlfn.FORMULATEXT(D18),D18) -> Деп.
A19: Благоприятная | B19: =ЭТАПЫ!C3*Решение!$B$15 -> 180 | C19: =ЭТАПЫ!D3*Решение!$C$15 -> 880 | D19: =ЭТАПЫ!E3*Решение!$D$15 -> 963 | E19: =SUM(B19:D19) -> 2023 | G19: =IFERROR(_xlfn.FORMULATEXT(B19),B19) -> 180 | H19: =IFERROR(_xlfn.FORMULATEXT(C19),C19) -> 880 | I19: =IFERROR(_xlfn.FORMULATEXT(D19),D19) -> 963
A20: Нейтральная | B20: =ЭТАПЫ!C4*Решение!$B$15 -> 157.5 | C20: =ЭТАПЫ!D4*Решение!$C$15 -> 816 | D20: =ЭТАПЫ!E4*Решение!$D$15 -> 927 | E20: =SUM(B20:D20) -> 1900.5 | G20: =IFERROR(_xlfn.FORMULATEXT(B20),B20) -> 157.5 | H20: =IFERROR(_xlfn.FORMULATEXT(C20),C20) -> 816 | I20: =IFERROR(_xlfn.FORMULATEXT(D20),D20) -> 927
A21: Негативная | B21: =ЭТАПЫ!C5*Решение!$B$15 -> 120 | C21: =ЭТАПЫ!D5*Решение!$C$15 -> 760 | D21: =ЭТАПЫ!E5*Решение!$D$15 -> 900 | E21: =SUM(B21:D21) -> 1780 | G21: =IFERROR(_xlfn.FORMULATEXT(B21),B21) -> 120 | H21: =IFERROR(_xlfn.FORMULATEXT(C21),C21) -> 760 | I21: =IFERROR(_xlfn.FORMULATEXT(D21),D21) -> 900
A22: Матожидание | B22: =SUMPRODUCT(ЭТАПЫ!$B$3:$B$5,B19:B21) -> 167.25 | C22: =SUMPRODUCT(ЭТАПЫ!$B$3:$B$5,C19:C21) -> 848.8 | D22: =SUMPRODUCT(ЭТАПЫ!$B$3:$B$5,D19:D21) -> 945.9 | E22: =SUM(B22:D22) -> 1961.95 | G22: =IFERROR(_xlfn.FORMULATEXT(B22),B22) -> 167.25 | H22: =IFERROR(_xlfn.FORMULATEXT(C22),C22) -> 848.8 | I22: =IFERROR(_xlfn.FORMULATEXT(D22),D22) -> 945.9
G23: =IFERROR(_xlfn.FORMULATEXT(B23),B23) -> 0 | H23: =IFERROR(_xlfn.FORMULATEXT(C23),C23) -> 0 | I23: =IFERROR(_xlfn.FORMULATEXT(D23),D23) -> 0
A24: Этап 2 | G24: =IFERROR(_xlfn.FORMULATEXT(B24),B24) -> 0 | H24: =IFERROR(_xlfn.FORMULATEXT(C24),C24) -> 0 | I24: =IFERROR(_xlfn.FORMULATEXT(D24),D24) -> 0
B25: Переменные | E25: Свободные деньги (остаток) | G25: =IFERROR(_xlfn.FORMULATEXT(B25),B25) -> Переменные | H25: =IFERROR(_xlfn.FORMULATEXT(C25),C25) -> 0 | I25: =IFERROR(_xlfn.FORMULATEXT(D25),D25) -> 0
B26: Сколько шагов добавить в ЦБ1 | C26: Сколько шагов добавить в ЦБ2 | D26: Сколько шагов добавить в Деп. | G26: =IFERROR(_xlfn.FORMULATEXT(B26),B26) -> Сколько шагов добавить в ЦБ1 | H26: =IFERROR(_xlfn.FORMULATEXT(C26),C26) -> Сколько шагов добавить в ЦБ2 | I26: =IFERROR(_xlfn.FORMULATEXT(D26),D26) -> Сколько шагов добавить в Деп.
B27: x1 | C27: x2 | D27: x3 | G27: =IFERROR(_xlfn.FORMULATEXT(B27),B27) -> x1 | H27: =IFERROR(_xlfn.FORMULATEXT(C27),C27) -> x2 | I27: =IFERROR(_xlfn.FORMULATEXT(D27),D27) -> x3
B28: -5 | C28: 0 | D28: 0 | G28: =IFERROR(_xlfn.FORMULATEXT(B28),B28) -> -5 | H28: =IFERROR(_xlfn.FORMULATEXT(C28),C28) -> 0 | I28: =IFERROR(_xlfn.FORMULATEXT(D28),D28) -> 0
A29: Изменения в деньгах | B29: =B28*ЭТАПЫ!B9 -> -125 | C29: =C28*ЭТАПЫ!C9 -> 0 | D29: =D28*ЭТАПЫ!D9 -> 0 | E29: =E12-B29-C29-D29-ABS(B29)*ЭТАПЫ!A17-ABS(Решение!C29)*ЭТАПЫ!B17-ABS(Решение!D29)*ЭТАПЫ!C17 -> 143 | G29: =IFERROR(_xlfn.FORMULATEXT(B29),B29) -> -125 | H29: =IFERROR(_xlfn.FORMULATEXT(C29),C29) -> 0 | I29: =IFERROR(_xlfn.FORMULATEXT(D29),D29) -> 0
G30: =IFERROR(_xlfn.FORMULATEXT(B30),B30) -> 0 | H30: =IFERROR(_xlfn.FORMULATEXT(C30),C30) -> 0 | I30: =IFERROR(_xlfn.FORMULATEXT(D30),D30) -> 0
A31: Начальные значения | B31: Всего ЦБ1 | C31: Всего ЦБ2 | D31: Всего Деп. | G31: =IFERROR(_xlfn.FORMULATEXT(B31),B31) -> Всего ЦБ1 | H31: =IFERROR(_xlfn.FORMULATEXT(C31),C31) -> Всего ЦБ2 | I31: =IFERROR(_xlfn.FORMULATEXT(D31),D31) -> Всего Деп.
B32: =B22+B29 -> 42.25 | C32: =C22+C29 -> 848.8 | D32: =D22+D29 -> 945.9 | G32: =IFERROR(_xlfn.FORMULATEXT(B32),B32) -> 42.25 | H32: =IFERROR(_xlfn.FORMULATEXT(C32),C32) -> 848.8 | I32: =IFERROR(_xlfn.FORMULATEXT(D32),D32) -> 945.9
G33: =IFERROR(_xlfn.FORMULATEXT(B33),B33) -> 0 | H33: =IFERROR(_xlfn.FORMULATEXT(C33),C33) -> 0 | I33: =IFERROR(_xlfn.FORMULATEXT(D33),D33) -> 0
A34: Ситуация | B34: Результат в конце этапа | G34: =IFERROR(_xlfn.FORMULATEXT(B34),B34) -> Результат в конце этапа | H34: =IFERROR(_xlfn.FORMULATEXT(C34),C34) -> 0 | I34: =IFERROR(_xlfn.FORMULATEXT(D34),D34) -> 0
B35: ЦБ1 | C35: ЦБ2 | D35: Деп. | E35: Итого | G35: =IFERROR(_xlfn.FORMULATEXT(B35),B35) -> ЦБ1 | H35: =IFERROR(_xlfn.FORMULATEXT(C35),C35) -> ЦБ2 | I35: =IFERROR(_xlfn.FORMULATEXT(D35),D35) -> Деп.
A36: Благоприятная | B36: =ЭТАПЫ!G3*B$32 -> 59.15 | C36: =ЭТАПЫ!H3*C$32 -> 976.12 | D36: =ЭТАПЫ!I3*D$32 -> 955.359 | E36: =SUM(B36:D36) -> 1990.629 | G36: =IFERROR(_xlfn.FORMULATEXT(B36),B36) -> 59.15 | H36: =IFERROR(_xlfn.FORMULATEXT(C36),C36) -> 976.12 | I36: =IFERROR(_xlfn.FORMULATEXT(D36),D36) -> 955.359
A37: Нейтральная | B37: =ЭТАПЫ!G4*B$32 -> 44.3625 | C37: =ЭТАПЫ!H4*C$32 -> 848.8 | D37: =ЭТАПЫ!I4*D$32 -> 945.9 | E37: =SUM(B37:D37) -> 1839.0625 | G37: =IFERROR(_xlfn.FORMULATEXT(B37),B37) -> 44.3625 | H37: =IFERROR(_xlfn.FORMULATEXT(C37),C37) -> 848.8 | I37: =IFERROR(_xlfn.FORMULATEXT(D37),D37) -> 945.9
A38: Негативная | B38: =ЭТАПЫ!G5*B$32 -> 25.35 | C38: =ЭТАПЫ!H5*C$32 -> 763.92 | D38: =ЭТАПЫ!I5*D$32 -> 945.9 | E38: =SUM(B38:D38) -> 1735.17 | G38: =IFERROR(_xlfn.FORMULATEXT(B38),B38) -> 25.35 | H38: =IFERROR(_xlfn.FORMULATEXT(C38),C38) -> 763.92 | I38: =IFERROR(_xlfn.FORMULATEXT(D38),D38) -> 945.9
A39: Матожидание | B39: =SUMPRODUCT(ЭТАПЫ!$F$3:$F$5,B36:B38) -> 39.2925 | C39: =SUMPRODUCT(ЭТАПЫ!$F$3:$F$5,C36:C38) -> 844.556 | D39: =SUMPRODUCT(ЭТАПЫ!$F$3:$F$5,D36:D38) -> 948.7377 | E39: =SUM(B39:D39) -> 1832.5862 | G39: =IFERROR(_xlfn.FORMULATEXT(B39),B39) -> 39.2925 | H39: =IFERROR(_xlfn.FORMULATEXT(C39),C39) -> 844.556 | I39: =IFERROR(_xlfn.FORMULATEXT(D39),D39) -> 948.7377
G40: =IFERROR(_xlfn.FORMULATEXT(B40),B40) -> 0 | H40: =IFERROR(_xlfn.FORMULATEXT(C40),C40) -> 0 | I40: =IFERROR(_xlfn.FORMULATEXT(D40),D40) -> 0
A41: Этап 3 | G41: =IFERROR(_xlfn.FORMULATEXT(B41),B41) -> 0 | H41: =IFERROR(_xlfn.FORMULATEXT(C41),C41) -> 0 | I41: =IFERROR(_xlfn.FORMULATEXT(D41),D41) -> 0
B42: Переменные | E42: Свободные деньги (остаток) | G42: =IFERROR(_xlfn.FORMULATEXT(B42),B42) -> Переменные | H42: =IFERROR(_xlfn.FORMULATEXT(C42),C42) -> 0 | I42: =IFERROR(_xlfn.FORMULATEXT(D42),D42) -> 0
...
